Workbook

Sheet BC năm 2025
A1: BÁO CÁO SẢN LƯỢNG ĐIỆN
A2: (Kèm theo Công văn số ………/SCT-QLNL ngày ……/ ……/ 2026 của Sở Công Thương)
A4: STT | B4: Tên nhà máy điện | C4: Tên đơn vị | D4: Địa chỉ | E4: Công suất | G4: Sản lượng theo tháng năm 2025 (kWh) | S4: Tổng cộng cả năm (kWh) | T4: Tổng cộng tháng 9
E5: MWp | F5: MW | G5: Tháng 1 | H5: Tháng 2 | I5: Tháng 3 | J5: Tháng 4 | K5: Tháng 5 | L5: Tháng 6 | M5: Tháng 7 | N5: Tháng 8 | O5: Tháng 9 | P5: Tháng 10 | Q5: Tháng 11 | R5: Tháng 12
A6: I | B6: NHÀ MÁY ĐIỆN GIÓ (12 nhà máy)
A7: 1 | B7: Nhà máy điện gió 7A | C7: Công ty TNHH MTV Điện gió Hà Đô Thuận Nam | D7: Thôn Quán Thẻ 1, xã Thuận Nam, tỉnh Khánh Hòa | F7: 50 | G7: 15550943 | H7: 14216635 | I7: 13646714 | J7: 8229488 | K7: 4630075 | L7: 8728843 | M7: 13604490 | N7: 10058261 | O7: 5434699 | P7: 3430997 | Q7: 10290616 | R7: 21984097 | S7: =SUM(G7:R7) -> 129805858 | T7: =SUM(G7:O7) -> 94100148
A8: 2 | B8: Nhà máy điện gió BIM 4 | C8: Công ty cổ phần Điện gió BIM | D8: Thôn Quán Thẻ 1, xã Thuận Nam, tỉnh Khánh Hòa | F8: 88 | G8: 37567025 | H8: 34089733 | I8: 29239645 | J8: 17878335 | K8: 11366298 | L8: 21812301 | M8: 29034521 | N8: 22491306 | O8: 12862944 | P8: 6968140 | Q8: 20179004 | R8: 38863577 | S8: =SUM(G8:R8) -> 282352829 | T8: =SUM(G8:O8) -> 216342108
A9: 3 | B9: Nhà máy điện gió Hanbaram lô 1 | C9: Công ty cổ phần Điện gió Hanbaram | D9: Km1535, Quốc lộ 1A, thôn Ấn Đạt, xã Thuận Bắc, tỉnh Khánh Hòa | F9: 48 | G9: 25619110 | H9: 21839264 | I9: 15131625 | J9: 10841836 | K9: 2865759 | L9: 3055499 | M9: 5533226 | N9: 2982301 | O9: 1677771 | P9: 6609246 | Q9: 11977667 | R9: 24805381 | S9: =SUM(G9:R9) -> 132938685 | T9: =SUM(G9:O9) -> 89546391
A10: 4 | B10: Nhà máy điện gió Hanbaram lô 2 | C10: Công ty cổ phần Điện gió Hanbaram | D10: Km1535, Quốc lộ 1A, thôn Ấn Đạt, xã Thuận Bắc, tỉnh Khánh Hòa | F10: 69 | G10: 32045575 | H10: 25828133 | I10: 18462770 | J10: 13042195 | K10: 3800678 | L10: 3992728.2 | M10: 7939177.8 | N10: 3188148.8 | O10: 2040617.5 | P10: 5810175.9 | Q10: 13284801 | R10: 27500346 | S10: =SUM(G10:R10) -> 1.5693535e+08 | T10: =SUM(G10:O10) -> 1.1034002e+08
A11: 5 | B11: Nhà máy điện gió Lợi Hải 2 | C11: Công ty cổ phần Phong điện Thuận Bình | D11: Thôn Ấn Đạt, xã Thuận Bắc, tỉnh Khánh Hòa | F11: 28.8 | G11: 17933220 | H11: 13657459 | I11: 11259575 | J11: 7655408 | K11: 2480254 | L11: 2264110 | M11: 4154927 | N11: 2387564 | O11: 1568364 | P11: 4680910 | Q11: 9297659 | R11: 17169816 | S11: =SUM(G11:R11) -> 94509266 | T11: =SUM(G11:O11) -> 63360881
A12: 6 | B12: Nhà máy điện gió Phước Hữu – Duyên Hải 1 | C12: Công ty TNHH Điện gió Phước Hữu – Duyên Hải 1 | D12: Thôn Hậu Sanh, xã Phước Hữu, tỉnh Khánh Hòa | F12: 29.7 | G12: 8207307.9 | H12: 8812008.3 | I12: 7787881.2 | J12: 3675096.6 | K12: 2542358.6 | L12: 5081163 | M12: 8343371.4 | N12: 5430203 | O12: 2472981.4 | P12: 1576020.2 | Q12: 5913342.4 | R12: 10702571 | S12: =SUM(G12:R12) -> 70544305 | T12: =SUM(G12:O12) -> 52352371
A13: 7 | B13: Nhà máy điện gió Phước Minh | C13: Công ty cổ phần Điện gió Adani Phước Minh | D13: Thôn Quán Thẻ 1, xã Thuận Nam, tỉnh Khánh Hòa | F13: 27.2 | G13: 8433537 | H13: 8356145 | I13: 7716768 | J13: 4478885 | K13: 2869997 | L13: 5224040 | M13: 7440560 | N13: 5198151 | O13: 2644104 | P13: 1190772 | Q13: 5104136 | R13: 11248771 | S13: =SUM(G13:R13) -> 69905866 | T13: =SUM(G13:O13) -> 52362187
A14: 8 | B14: Nhà máy điện gió số 5 Ninh Thuận | C14: Công ty cổ phần Điện gió Phước Hữu | D14: Thôn Hậu Sanh, xã Phước Hữu, tỉnh Khánh Hòa | F14: 46.2 | G14: 8121276 | H14: 9082485 | I14: 7871663 | J14: 3524900 | K14: 2420954 | L14: 4853437 | M14: 9097756 | N14: 5966580 | O14: 2684420 | P14: 1597145 | Q14: 5490858 | R14: 11384561 | S14: =SUM(G14:R14) -> 72096035 | T14: =SUM(G14:O14) -> 53623471
A15: 9 | B15: Nhà máy điện gió Trung Nam | C15: Công ty cổ phần Điện gió Trung Nam | D15: Thôn Ba Tháp, xã Thuận Bắc, tỉnh Khánh Hòa | F15: 151.95 | G15: 72858703 | H15: 52179554 | I15: 34590000 | J15: 21543157 | K15: 5470405 | L15: 5182714 | M15: 9943570 | N15: 4170416 | O15: 3139833 | P15: 9365879 | Q15: 28597633 | R15: 57403112 | S15: =SUM(G15:R15) -> 304444976 | T15: =SUM(G15:O15) -> 209078352
A16: 10 | B16: Nhà máy điện gió Đầm Nại | C16: Công ty cổ phần Điện gió Đầm Nại | D16: Thôn Láng Me, xã Ninh Hải, tỉnh Khánh Hòa | F16: 39.375 | G16: 21976098 | H16: 16799036 | I16: 12654950 | J16: 8478333 | K16: 2381951 | L16: 2422351 | M16: 4045626 | N16: 2149029 | O16: 1437094 | P16: 3779783 | Q16: 10019751 | R16: 19929198 | S16: =SUM(G16:R16) -> 106073200 | T16: =SUM(G16:O16) -> 72344468
A17: 11 | B17: Nhà máy điện gió Mũi Dinh | C17: Công ty TNHH Điện gió Mũi Dinh | D17: Thôn Từ Thiện, xã Phước Dinh, tỉnh Khánh Hòa | F17: 37.6 | G17: 14684036 | H17: 11740618 | I17: 9240614 | J17: 5228141 | K17: 2432130 | L17: 5866028 | M17: 9372726 | N17: 6345523 | O17: 3302539 | P17: 2863019 | Q17: 7438717 | R17: 12645342 | S17: =SUM(G17:R17) -> 91159433 | T17: =SUM(G17:O17) -> 68212355
A18: 12 | B18: Nhà máy điện gió Win Energy Chính Thắng | C18: Công ty TNHH Điện gió Chính Thắng | D18: Xã Thuận Nam, tỉnh Khánh Hòa | F18: 49.8 | G18: 15286260 | H18: 15740260 | I18: 13978150 | J18: 7578580 | K18: 4891600 | L18: 8370380 | M18: 14230110 | N18: 9731460 | O18: 4918230 | P18: 3523760 | Q18: 10243540 | R18: 20159310 | S18: =SUM(G18:R18) -> 128651640 | T18: =SUM(G18:O18) -> 94725030
B19: TỔNG | E19: =SUM(E7:E18) -> 0 | F19: =SUM(F7:F18) -> 665.625 | G19: =SUM(G7:G18) -> 2.7828309e+08 | H19: =SUM(H7:H18) -> 2.3234133e+08 | I19: =SUM(I7:I18) -> 1.8158036e+08 | J19: =SUM(J7:J18) -> 1.1215435e+08 | K19: =SUM(K7:K18) -> 48152460 | L19: =SUM(L7:L18) -> 76853594 | ... S19: =SUM(S7:S18) -> 1.6394174e+09 | T19: =SUM(G19:O19) -> 1.1763878e+09
A20: II | B20: NHÀ MÁY ĐIỆN MẶT TRỜI (45 nhà máy)
A21: 1 | B21: Nhà máy điện mặt trời Adani Phước Minh | C21: Công ty cổ phần Điện mặt trời Adani Phước Minh | D21: Thôn Quán Thẻ 1, xã Thuận Nam, tỉnh Khánh Hòa
A22: 2 | B22: Nhà máy điện mặt trời AMI Khánh Hòa | C22: Công ty cổ phần năng lượng AMI Khánh Hòa | D22: Thôn Vĩnh Đông, xã Cam An, tỉnh Khánh Hòa
A23: 3 | B23: Nhà máy điện mặt trời BP Solar 1 | C23: Công ty cổ phần BP Solar | D23: Thôn Thành Đức, xã Phước Hữu, tỉnh Khánh Hòa
A24: 4 | B24: Nhà máy điện mặt trời Cam Lâm VN | C24: Công ty cổ phần Cam Lâm Solar | D24: Thôn Tân An, xã Cam An, tỉnh Khánh Hòa
A25: 5 | B25: Nhà máy điện mặt trời CMX Renewable Energy Việt Nam | C25: Công ty cổ phần Điện mặt trời CMX RE Sunseap Việt Nam | D25: Thôn Tân Mỹ, xã Mỹ Sơn, tỉnh Khánh Hòa
A26: 6 | B26: Nhà máy điện mặt trời Điện lực miền Trung | C26: Công ty Dịch vụ Điện lực miền Trung | D26: Thôn Tân An, Xã Cam An, tỉnh Khánh Hòa
A27: 7 | B27: Nhà máy điện mặt trời Gelex Ninh Thuận | C27: Công ty TNHH Năng lượng Gelex Ninh Thuận | D27: Thôn Sơn Hải, xã Phước Dinh, tỉnh Khánh Hòa
A28: 8 | B28: Nhà máy điện mặt trời Hồ Bầu Ngứ | C28: Công ty cổ phần Đầu tư xây dựng và Phát triển Trường Thành | D28: Xã Phước Dinh, tỉnh Khánh Hòa
A29: 9 | B29: Nhà máy điện mặt trời Hồ Núi Một | C29: Công ty cổ phần Đầu tư xây dựng và Phát triển Trường Thành | D29: Thôn Bầu Ngứ, xã Phước Dinh, tỉnh Khánh Hòa
A30: 10 | B30: Nhà máy điện mặt trời KN Cam Lâm | C30: Công ty cổ phần Điện mặt trời KN Cam Lâm | D30: Thôn Tân An, xã Cam An, tỉnh Khánh Hòa
A31: 11 | B31: Nhà máy điện mặt trời KN Vạn Ninh | C31: Công ty TNHH Đầu tư và Phát triển Điện mặt trời KN Vạn Ninh | D31: Thôn Xuân Tây, xã Vạn Hưng, tỉnh Khánh Hòa
A32: 12 | B32: Nhà máy điện mặt trời Long Sơn | C32: Công ty cổ phần Năng lượng Long Sơn | D32: Thôn Đá Bàn, phường Bắc Ninh Hòa, tỉnh Khánh Hòa
... A65: 45 | B65: Nhà máy điện mặt trời Sinenergy Ninh Thuận 1 | C65: Công ty TNHH Năng lượng Sinenergy Ninh Thuận | D65: Thôn Tân Đức, xã Phước Hữu, tỉnh Khánh Hòa
A66: TỔNG | E66: =SUM(E21:E65) -> 0 | F66: =SUM(F21:F65) -> 0 | G66: =SUM(G21:G65) -> 0 | H66: =SUM(H21:H65) -> 0 | I66: =SUM(I21:I65) -> 0 | J66: =SUM(J21:J65) -> 0 | K66: =SUM(K21:K65) -> 0 | L66: =SUM(L21:L65) -> 0 | ... R66: =SUM(R21:R65) -> 0
A67: III | B67: NHÀ MÁY THỦY ĐIỆN (14 nhà máy)
A68: 1 | B68: Nhà máy thủy điện Đa Nhim | C68: Công ty cổ phần Thủy điện Đa Nhim – Hàm Thuận – Đa Mi | D68: Xã Lâm Sơn, tỉnh Khánh Hòa
A69: 2 | B69: Nhà máy thủy điện Sông Pha | C69: Công ty cổ phần Thủy điện Đa Nhim – Hàm Thuận – Đa Mi | D69: Xã Lâm Sơn, tỉnh Khánh Hòa
A70: 3 | B70: Nhà máy thủy điện Đa Nhim mở rộng | C70: Công ty cổ phần Thủy điện Đa Nhim – Hàm Thuận – Đa Mi | D70: Xã Lâm Sơn, tỉnh Khánh Hòa
A71: 4 | B71: Nhà máy thủy điện Hạ Sông Pha 1 | C71: Công ty cổ phần thủy điện Hạ Sông Pha | D71: Thôn Lâm Hà, xã Lâm Sơn, tỉnh Khánh Hòa
A72: 5 | B72: Nhà máy thủy điện Hạ Sông Pha 2 | C72: Công ty cổ phần thủy điện Hạ Sông Pha | D72: Thôn Lâm Hà, xã Lâm Sơn, tỉnh Khánh Hòa
A73: 6 | B73: Nhà máy thủy điện Mỹ Sơn | C73: Công ty cổ phần Thủy điện Mỹ Sơn | D73: Thôn Tân Mỹ, xã Mỹ Sơn, tỉnh Khánh Hòa
...

Sheet BC 15 hàng tháng
A1: BÁO CÁO SẢN LƯỢNG ĐIỆN
A2: (Kèm theo Công văn số ………/SCT-QLNL ngày ……/ ……/ 2026 của Sở Công Thương)
A4: STT | B4: Tên nhà máy điện | C4: Tên đơn vị | D4: Địa chỉ | E4: Công suất | G4: Kế hoạch 2026 (kWh) | H4: Sản lượng theo tháng năm 2026 (kWh) | T4: Tổng cộng (kWh) | U4: So với cùng kỳ (%)
E5: MWp | F5: MW | H5: Tháng 1 | I5: Tháng 2 | J5: Tháng 3 | K5: Tháng 4 | L5: Tháng 5 | M5: Tháng 6 | N5: Tháng 7 | O5: Tháng 8 | P5: Tháng 9 | Q5: Tháng 10 | R5: Tháng 11 | S5: Tháng 12
A6: I | B6: NHÀ MÁY ĐIỆN GIÓ (13 nhà máy) | T6: =SUM(H6:S6) -> 0
A7: 1 | B7: Nhà máy điện gió 7A | C7: Công ty TNHH MTV Điện gió Hà Đô Thuận Nam | D7: Thôn Quán Thẻ 1, xã Thuận Nam, tỉnh Khánh Hòa | F7: ='BC năm 2025'!F7 -> 50 | G7: 135614593 | H7: 15408572 | I7: 15148881 | J7: 12024618 | K7: 8723450 | L7: 7432276 | M7: 11206429 | N7: 14007504 | O7: 18121954 | P7: 5257059 | T7: =SUM(H7:S7) -> 107330743 | U7: =T7/'BC năm 2025'!T7 -> 1.1406012
A8: 2 | B8: Nhà máy điện gió BIM 4 | C8: Công ty cổ phần Điện gió BIM | D8: Thôn Quán Thẻ 1, xã Thuận Nam, tỉnh Khánh Hòa | F8: ='BC năm 2025'!F8 -> 88 | G8: 317230000 | H8: 30284554 | I8: 28229840 | J8: 24173657 | K8: 20425278 | L8: 16796752 | M8: 24962968 | N8: 29092945 | O8: 30349756 | P8: 8777287 | T8: =SUM(H8:S8) -> 213093037 | U8: =T8/'BC năm 2025'!T8 -> 0.98498179
A9: 3 | B9: Nhà máy điện gió Hanbaram lô 1 | C9: Công ty cổ phần Điện gió Hanbaram | D9: Km1535, Quốc lộ 1A, thôn Ấn Đạt, xã Thuận Bắc, tỉnh Khánh Hòa | F9: ='BC năm 2025'!F9 -> 48 | G9: 1.1966269e+08 | H9: 23195501 | I9: 17263432 | J9: 11981450 | K9: 3491990.7 | L9: 6029697 | M9: 2742420 | N9: 3937254 | O9: 7717137 | P9: 1324938 | T9: =SUM(H9:S9) -> 77683820 | U9: =T9/'BC năm 2025'!T9 -> 0.86752597
A10: 4 | B10: Nhà máy điện gió Hanbaram lô 2 | C10: Công ty cổ phần Điện gió Hanbaram | D10: Km1535, Quốc lộ 1A, thôn Ấn Đạt, xã Thuận Bắc, tỉnh Khánh Hòa | F10: ='BC năm 2025'!F10 -> 69 | G10: 1.7201512e+08 | H10: 28850367 | I10: 23688798 | J10: 15012915 | K10: 4495899.9 | L10: 7917981 | M10: 2676881 | N10: 4167530.2 | O10: 11483394 | P10: 1767817 | T10: =SUM(H10:S10) -> 1.0006158e+08 | U10: =T10/'BC năm 2025'!T10 -> 0.90684758
A11: 5 | B11: Nhà máy điện gió Lợi Hải 2 | C11: Công ty cổ phần Phong điện Thuận Bình | D11: Thôn Ấn Đạt, xã Thuận Bắc, tỉnh Khánh Hòa | F11: ='BC năm 2025'!F11 -> 28.8 | G11: 88400000 | H11: 17328712 | I11: 13026868 | J11: 9870288 | K11: 4098812 | L11: 5370927 | M11: 2730515 | N11: 3184884 | O11: 6388525 | P11: 1514014 | T11: =SUM(H11:S11) -> 63513545 | U11: =T11/'BC năm 2025'!T11 -> 1.0024094
A12: 6 | B12: Nhà máy điện gió Phước Hữu – Duyên Hải 1 | C12: Công ty TNHH Điện gió Phước Hữu – Duyên Hải 1 | D12: Thôn Hậu Sanh, xã Phước Hữu, tỉnh Khánh Hòa | F12: ='BC năm 2025'!F12 -> 29.7 | G12: 67938978 | H12: 6168627.2 | I12: 7690575 | J12: 6085015 | K12: 3676414.9 | L12: 3821507.4 | M12: 5524699.4 | N12: 7551820.7 | O12: 11436126 | P12: 2887050.6 | T12: =SUM(H12:S12) -> 54841836 | U12: =T12/'BC năm 2025'!T12 -> 1.0475521
A13: 7 | B13: Nhà máy điện gió Phước Minh | C13: Công ty cổ phần Điện gió Adani Phước Minh | D13: Thôn Quán Thẻ 1, xã Thuận Nam, tỉnh Khánh Hòa | F13: ='BC năm 2025'!F13 -> 27.2 | G13: 70400000 | H13: 7005753 | I13: 7569941 | J13: 6280691 | K13: 4829014 | L13: 4165641 | M13: 4908097 | N13: 4940834 | O13: 7623266 | P13: 1603921 | T13: =SUM(H13:S13) -> 48927158 | U13: =T13/'BC năm 2025'!T13 -> 0.93439867
A14: 8 | B14: Nhà máy điện gió số 5 Ninh Thuận | C14: Công ty cổ phần Điện gió Phước Hữu | D14: Thôn Hậu Sanh, xã Phước Hữu, tỉnh Khánh Hòa | F14: ='BC năm 2025'!F14 -> 46.2 | G14: 67051226 | H14: 3809130 | I14: 5142890 | J14: 5023700 | K14: 3082500 | L14: 2693720 | M14: 3191220 | N14: 4374070 | O14: 5477840 | P14: 3483700 | T14: =SUM(H14:S14) -> 36278770 | U14: =T14/'BC năm 2025'!T14 -> 0.67654647
A15: 9 | B15: Nhà máy điện gió Trung Nam | C15: Công ty cổ phần Điện gió Trung Nam | D15: Thôn Ba Tháp, xã Thuận Bắc, tỉnh Khánh Hòa | F15: ='BC năm 2025'!F15 -> 151.95 | G15: 283976400 | H15: 64201810 | I15: 44881997 | J15: 28905375 | K15: 8362600 | L15: 13094171 | M15: 4504643 | N15: 4474577 | O15: 11467699 | P15: 2953310 | T15: =SUM(H15:S15) -> 182846182 | U15: =T15/'BC năm 2025'!T15 -> 0.87453426
A16: 10 | B16: Nhà máy điện gió Đầm Nại | C16: Công ty cổ phần Điện gió Đầm Nại | D16: Thôn Láng Me, xã Ninh Hải, tỉnh Khánh Hòa | F16: ='BC năm 2025'!F16 -> 39.375 | G16: 110895450 | H16: 21296156 | I16: 16130236 | J16: 10346207 | K16: 3498065 | L16: 4900623 | M16: 2104050 | N16: 2189809 | O16: 5574490 | P16: 1081147 | T16: =SUM(H16:S16) -> 67120783 | U16: =T16/'BC năm 2025'!T16 -> 0.92779427
A17: 11 | B17: Nhà máy điện gió Mũi Dinh | C17: Công ty TNHH Điện gió Mũi Dinh | D17: Thôn Từ Thiện, xã Phước Dinh, tỉnh Khánh Hòa | F17: ='BC năm 2025'!F17 -> 37.6 | G17: 86155093 | H17: 12084492 | I17: 9106298 | J17: 7108622 | K17: 2884567 | L17: 4029529 | M17: 5529432 | N17: 8079703 | O17: 11955636 | P17: 3164416 | T17: =SUM(H17:P17) -> 63942695 | U17: =T17/'BC năm 2025'!T17 -> 0.93740635
A18: 12 | B18: Nhà máy điện gió Win Energy Chính Thắng | C18: Công ty TNHH Điện gió Chính Thắng | D18: Xã Thuận Nam, tỉnh Khánh Hòa | F18: ='BC năm 2025'!F18 -> 49.8 | G18: 12395150 | H18: 12395150 | I18: 14405370 | J18: 12147140 | K18: 7582170 | L18: 7582170 | M18: 7768100 | N18: 9570210 | O18: 13611330 | P18: 18822630 | T18: =SUM(H18:S18) -> 103884270 | U18: =T18/'BC năm 2025'!T18 -> 1.0966929
B19: TỔNG | E19: =SUM(E7:E18) -> 0 | F19: =SUM(F7:F18) -> 665.625 | G19: =SUM(G7:G18) -> 1531734695 | H19: =SUM(H7:H18) -> 2.4202882e+08 | I19: =SUM(I7:I18) -> 202285126 | J19: =SUM(J7:J18) -> 1.4895968e+08 | K19: =SUM(K7:K18) -> 75150762 | L19: =SUM(L7:L18) -> 83834994 | ... S19: =SUM(S7:S18) -> 0 | T19: =SUM(H19:S19) -> 1.1195244e+09 | U19: =T19/'BC năm 2025'!T19 -> 0.95166274
A20: II | B20: NHÀ MÁY ĐIỆN MẶT TRỜI (45 nhà máy) | T20: =SUM(H20:S20) -> 0
A21: 1 | B21: Nhà máy điện mặt trời Adani Phước Minh | C21: Công ty cổ phần Điện mặt trời Adani Phước Minh | D21: Thôn Quán Thẻ 1, xã Thuận Nam, tỉnh Khánh Hòa | T21: =SUM(H21:S21) -> 0
A22: 2 | B22: Nhà máy điện mặt trời AMI Khánh Hòa | C22: Công ty cổ phần năng lượng AMI Khánh Hòa | D22: Thôn Vĩnh Đông, xã Cam An, tỉnh Khánh Hòa | T22: =SUM(H22:S22) -> 0
A23: 3 | B23: Nhà máy điện mặt trời BP Solar 1 | C23: Công ty cổ phần BP Solar | D23: Thôn Thành Đức, xã Phước Hữu, tỉnh Khánh Hòa | T23: =SUM(H23:S23) -> 0
A24: 4 | B24: Nhà máy điện mặt trời Cam Lâm VN | C24: Công ty cổ phần Cam Lâm Solar | D24: Thôn Tân An, xã Cam An, tỉnh Khánh Hòa | T24: =SUM(H24:S24) -> 0
A25: 5 | B25: Nhà máy điện mặt trời CMX Renewable Energy Việt Nam | C25: Công ty cổ phần Điện mặt trời CMX RE Sunseap Việt Nam | D25: Thôn Tân Mỹ, xã Mỹ Sơn, tỉnh Khánh Hòa | T25: =SUM(H25:S25) -> 0
A26: 6 | B26: Nhà máy điện mặt trời Điện lực miền Trung | C26: Công ty Dịch vụ Điện lực miền Trung | D26: Thôn Tân An, Xã Cam An, tỉnh Khánh Hòa | T26: =SUM(H26:S26) -> 0
A27: 7 | B27: Nhà máy điện mặt trời Gelex Ninh Thuận | C27: Công ty TNHH Năng lượng Gelex Ninh Thuận | D27: Thôn Sơn Hải, xã Phước Dinh, tỉnh Khánh Hòa | T27: =SUM(H27:S27) -> 0
A28: 8 | B28: Nhà máy điện mặt trời Hồ Bầu Ngứ | C28: Công ty cổ phần Đầu tư xây dựng và Phát triển Trường Thành | D28: Xã Phước Dinh, tỉnh Khánh Hòa | T28: =SUM(H28:S28) -> 0
A29: 9 | B29: Nhà máy điện mặt trời Hồ Núi Một | C29: Công ty cổ phần Đầu tư xây dựng và Phát triển Trường Thành | D29: Thôn Bầu Ngứ, xã Phước Dinh, tỉnh Khánh Hòa | T29: =SUM(H29:S29) -> 0
A30: 10 | B30: Nhà máy điện mặt trời KN Cam Lâm | C30: Công ty cổ phần Điện mặt trời KN Cam Lâm | D30: Thôn Tân An, xã Cam An, tỉnh Khánh Hòa | T30: =SUM(H30:S30) -> 0
A31: 11 | B31: Nhà máy điện mặt trời KN Vạn Ninh | C31: Công ty TNHH Đầu tư và Phát triển Điện mặt trời KN Vạn Ninh | D31: Thôn Xuân Tây, xã Vạn Hưng, tỉnh Khánh Hòa | T31: =SUM(H31:S31) -> 0
A32: 12 | B32: Nhà máy điện mặt trời Long Sơn | C32: Công ty cổ phần Năng lượng Long Sơn | D32: Thôn Đá Bàn, phường Bắc Ninh Hòa, tỉnh Khánh Hòa | T32: =SUM(H32:S32) -> 0
... A65: 45 | B65: Nhà máy điện mặt trời Sinenergy Ninh Thuận 1 | C65: Công ty TNHH Năng lượng Sinenergy Ninh Thuận | D65: Thôn Tân Đức, xã Phước Hữu, tỉnh Khánh Hòa | T65: =SUM(H65:S65) -> 0
A66: TỔNG | E66: =SUM(E21:E65) -> 0 | F66: =SUM(F21:F65) -> 0 | G66: =SUM(G21:G65) -> 0 | H66: =SUM(H21:H65) -> 0 | I66: =SUM(I21:I65) -> 0 | J66: =SUM(J21:J65) -> 0 | K66: =SUM(K21:K65) -> 0 | L66: =SUM(L21:L65) -> 0 | ... S66: =SUM(S21:S65) -> 0 | T66: =SUM(H66:S66) -> 0
A67: III | B67: NHÀ MÁY THỦY ĐIỆN (14 nhà máy) | T67: =SUM(H67:S67) -> 0
A68: 1 | B68: Nhà máy thủy điện Đa Nhim | C68: Công ty cổ phần Thủy điện Đa Nhim – Hàm Thuận – Đa Mi | D68: Xã Lâm Sơn, tỉnh Khánh Hòa | T68: =SUM(H68:S68) -> 0
A69: 2 | B69: Nhà máy thủy điện Sông Pha | C69: Công ty cổ phần Thủy điện Đa Nhim – Hàm Thuận – Đa Mi | D69: Xã Lâm Sơn, tỉnh Khánh Hòa | T69: =SUM(H69:S69) -> 0
A70: 3 | B70: Nhà máy thủy điện Đa Nhim mở rộng | C70: Công ty cổ phần Thủy điện Đa Nhim – Hàm Thuận – Đa Mi | D70: Xã Lâm Sơn, tỉnh Khánh Hòa | T70: =SUM(H70:S70) -> 0
A71: 4 | B71: Nhà máy thủy điện Hạ Sông Pha 1 | C71: Công ty cổ phần thủy điện Hạ Sông Pha | D71: Thôn Lâm Hà, xã Lâm Sơn, tỉnh Khánh Hòa | T71: =SUM(H71:S71) -> 0
A72: 5 | B72: Nhà máy thủy điện Hạ Sông Pha 2 | C72: Công ty cổ phần thủy điện Hạ Sông Pha | D72: Thôn Lâm Hà, xã Lâm Sơn, tỉnh Khánh Hòa | T72: =SUM(H72:S72) -> 0
A73: 6 | B73: Nhà máy thủy điện Mỹ Sơn | C73: Công ty cổ phần Thủy điện Mỹ Sơn | D73: Thôn Tân Mỹ, xã Mỹ Sơn, tỉnh Khánh Hòa | T73: =SUM(H73:S73) -> 0
...

Sheet BC hết tháng
A1: BÁO CÁO SẢN LƯỢNG ĐIỆN
A2: (Kèm theo Công văn số ………/SCT-QLNL ngày ……/ ……/ 2026 của Sở Công Thương)
A4: STT | B4: Tên nhà máy điện | C4: Tên đơn vị | D4: Địa chỉ | E4: Công suất | G4: Kế hoạch 2026 (kWh) | H4: Sản lượng theo tháng năm 2026 (kWh) | T4: Tổng cộng (kWh) | U4: So với cùng kỳ (%)
E5: MWp | F5: MW | H5: Tháng 1 | I5: Tháng 2 | J5: Tháng 3 | K5: Tháng 4 | L5: Tháng 5 | M5: Tháng 6 | N5: Tháng 7 | O5: Tháng 8 | P5: Tháng 9 | Q5: Tháng 10 | R5: Tháng 11 | S5: Tháng 12
A6: I | B6: NHÀ MÁY ĐIỆN GIÓ (13 nhà máy)
A7: 1 | B7: Nhà máy điện gió 7A | C7: Công ty TNHH MTV Điện gió Hà Đô Thuận Nam | D7: Thôn Quán Thẻ 1, xã Thuận Nam, tỉnh Khánh Hòa | F7: ='BC năm 2025'!F7 -> 50 | G7: ='BC 15 hàng tháng'!G7 -> 135614593 | H7: 15408572 | I7: 15148881 | J7: 12024618 | K7: 8723450 | L7: 7432276 | M7: 11206429 | N7: 14007504 | O7: 18121954 | T7: =SUM(H7:S7) -> 102073684
A8: 2 | B8: Nhà máy điện gió BIM 4 | C8: Công ty cổ phần Điện gió BIM | D8: Thôn Quán Thẻ 1, xã Thuận Nam, tỉnh Khánh Hòa | F8: ='BC năm 2025'!F8 -> 88 | G8: ='BC 15 hàng tháng'!G8 -> 317230000 | H8: 30284554 | I8: 28229840 | J8: 24173657 | K8: 20425278 | L8: 16796752 | M8: 24962968 | N8: 29092945 | O8: 30349756 | T8: =SUM(H8:S8) -> 204315750
A9: 3 | B9: Nhà máy điện gió Hanbaram lô 1 | C9: Công ty cổ phần Điện gió Hanbaram | D9: Km1535, Quốc lộ 1A, thôn Ấn Đạt, xã Thuận Bắc, tỉnh Khánh Hòa | F9: ='BC năm 2025'!F9 -> 48 | G9: ='BC 15 hàng tháng'!G9 -> 1.1966269e+08 | H9: 23195501 | I9: 17263432 | J9: 11981450 | K9: 3491990.7 | L9: 6029697 | M9: 2742420 | N9: 3937254 | O9: 7717137 | T9: =SUM(H9:S9) -> 76358882
A10: 4 | B10: Nhà máy điện gió Hanbaram lô 2 | C10: Công ty cổ phần Điện gió Hanbaram | D10: Km1535, Quốc lộ 1A, thôn Ấn Đạt, xã Thuận Bắc, tỉnh Khánh Hòa | F10: ='BC năm 2025'!F10 -> 69 | G10: ='BC 15 hàng tháng'!G10 -> 1.7201512e+08 | H10: 28850367 | I10: 23688798 | J10: 15012915 | K10: 4495899.9 | L10: 7917981 | M10: 2676881 | N10: 4167530.2 | O10: 11483394 | T10: =SUM(H10:S10) -> 98293767
A11: 5 | B11: Nhà máy điện gió Lợi Hải 2 | C11: Công ty cổ phần Phong điện Thuận Bình | D11: Thôn Ấn Đạt, xã Thuận Bắc, tỉnh Khánh Hòa | F11: ='BC năm 2025'!F11 -> 28.8 | G11: ='BC 15 hàng tháng'!G11 -> 88400000 | H11: 17328712 | I11: 13026868 | J11: 9870288 | K11: 4098812 | L11: 5370927 | M11: 2730515 | N11: 3184884 | O11: 6388525 | T11: =SUM(H11:S11) -> 61999531
A12: 6 | B12: Nhà máy điện gió Phước Hữu – Duyên Hải 1 | C12: Công ty TNHH Điện gió Phước Hữu – Duyên Hải 1 | D12: Thôn Hậu Sanh, xã Phước Hữu, tỉnh Khánh Hòa | F12: ='BC năm 2025'!F12 -> 29.7 | G12: ='BC 15 hàng tháng'!G12 -> 67938978 | H12: 6168627.2 | I12: 7690575 | J12: 6085015 | K12: 3676414.9 | L12: 3821507.4 | M12: 5524699.4 | N12: 7551820.7 | O12: 11436126 | T12: =SUM(H12:S12) -> 51954785
A13: 7 | B13: Nhà máy điện gió Phước Minh | C13: Công ty cổ phần Điện gió Adani Phước Minh | D13: Thôn Quán Thẻ 1, xã Thuận Nam, tỉnh Khánh Hòa | F13: ='BC năm 2025'!F13 -> 27.2 | G13: ='BC 15 hàng tháng'!G13 -> 70400000 | H13: 7005753 | I13: 7569941 | J13: 6280691 | K13: 4829014 | L13: 4165641 | M13: 4908097 | N13: 4940834 | O13: 7623266 | T13: =SUM(H13:S13) -> 47323237
A14: 8 | B14: Nhà máy điện gió số 5 Ninh Thuận | C14: Công ty cổ phần Điện gió Phước Hữu | D14: Thôn Hậu Sanh, xã Phước Hữu, tỉnh Khánh Hòa | F14: ='BC năm 2025'!F14 -> 46.2 | G14: ='BC 15 hàng tháng'!G14 -> 67051226 | H14: 6721807 | I14: 8256743 | J14: 6409240 | K14: 4236870 | L14: 4210350 | M14: 5685844 | N14: 8707539 | O14: 11988325 | T14: =SUM(H14:S14) -> 56216718
A15: 9 | B15: Nhà máy điện gió Trung Nam | C15: Công ty cổ phần Điện gió Trung Nam | D15: Thôn Ba Tháp, xã Thuận Bắc, tỉnh Khánh Hòa | F15: ='BC năm 2025'!F15 -> 151.95 | G15: ='BC 15 hàng tháng'!G15 -> 283976400 | H15: 64201810 | I15: 44881997 | J15: 28905375 | K15: 8362600 | L15: 13094171 | M15: 4504643 | N15: 4474577 | O15: 11467699 | T15: =SUM(H15:S15) -> 179892872
A16: 10 | B16: Nhà máy điện gió Đầm Nại | C16: Công ty cổ phần Điện gió Đầm Nại | D16: Thôn Láng Me, xã Ninh Hải, tỉnh Khánh Hòa | F16: ='BC năm 2025'!F16 -> 39.375 | G16: ='BC 15 hàng tháng'!G16 -> 110895450 | H16: 21296156 | I16: 16130236 | J16: 10346207 | K16: 3498065 | L16: 4900623 | M16: 2104050 | N16: 2189809 | O16: 5574490 | T16: =SUM(H16:S16) -> 66039636
A17: 11 | B17: Nhà máy điện gió Mũi Dinh | C17: Công ty TNHH Điện gió Mũi Dinh | D17: Thôn Từ Thiện, xã Phước Dinh, tỉnh Khánh Hòa | F17: ='BC năm 2025'!F17 -> 37.6 | G17: ='BC 15 hàng tháng'!G17 -> 86155093 | H17: 12084492 | I17: 9106298 | J17: 7108622 | K17: 2884567 | L17: 4029529 | M17: 5529432 | N17: 8079703 | O17: 11955636 | T17: =SUM(H17:S17) -> 60778279
A18: 12 | B18: Nhà máy điện gió Win Energy Chính Thắng | C18: Công ty TNHH Điện gió Chính Thắng | D18: Xã Thuận Nam, tỉnh Khánh Hòa | F18: ='BC năm 2025'!F18 -> 49.8 | G18: ='BC 15 hàng tháng'!G18 -> 12395150 | H18: 14405370 | I18: 12147140 | J18: 7582170 | K18: 7582170 | L18: 7768100 | M18: 9570210 | N18: 13611330 | O18: 18822630 | T18: =SUM(H18:S18) -> 91489120
B19: TỔNG | E19: =SUM(E7:E18) -> 0 | F19: =SUM(F7:F18) -> 665.625 | G19: =SUM(G7:G18) -> 1531734695 | H19: =SUM(H7:H18) -> 2.4695172e+08 | I19: =SUM(I7:I18) -> 203140749 | J19: =SUM(J7:J18) -> 1.4578025e+08 | K19: =SUM(K7:K18) -> 76305132 | L19: =SUM(L7:L18) -> 85537554 | ... S19: =SUM(S7:S18) -> 0 | T19: =SUM(H19:S19) -> 1.0967363e+09
A20: II | B20: NHÀ MÁY ĐIỆN MẶT TRỜI (45 nhà máy) | T20: =SUM(H20:S20) -> 0
A21: 1 | B21: Nhà máy điện mặt trời Adani Phước Minh | C21: Công ty cổ phần Điện mặt trời Adani Phước Minh | D21: Thôn Quán Thẻ 1, xã Thuận Nam, tỉnh Khánh Hòa | T21: =SUM(H21:S21) -> 0
A22: 2 | B22: Nhà máy điện mặt trời AMI Khánh Hòa | C22: Công ty cổ phần năng lượng AMI Khánh Hòa | D22: Thôn Vĩnh Đông, xã Cam An, tỉnh Khánh Hòa | T22: =SUM(H22:S22) -> 0
A23: 3 | B23: Nhà máy điện mặt trời BP Solar 1 | C23: Công ty cổ phần BP Solar | D23: Thôn Thành Đức, xã Phước Hữu, tỉnh Khánh Hòa | T23: =SUM(H23:S23) -> 0
A24: 4 | B24: Nhà máy điện mặt trời Cam Lâm VN | C24: Công ty cổ phần Cam Lâm Solar | D24: Thôn Tân An, xã Cam An, tỉnh Khánh Hòa | T24: =SUM(H24:S24) -> 0
A25: 5 | B25: Nhà máy điện mặt trời CMX Renewable Energy Việt Nam | C25: Công ty cổ phần Điện mặt trời CMX RE Sunseap Việt Nam | D25: Thôn Tân Mỹ, xã Mỹ Sơn, tỉnh Khánh Hòa | T25: =SUM(H25:S25) -> 0
A26: 6 | B26: Nhà máy điện mặt trời Điện lực miền Trung | C26: Công ty Dịch vụ Điện lực miền Trung | D26: Thôn Tân An, Xã Cam An, tỉnh Khánh Hòa | T26: =SUM(H26:S26) -> 0
A27: 7 | B27: Nhà máy điện mặt trời Gelex Ninh Thuận | C27: Công ty TNHH Năng lượng Gelex Ninh Thuận | D27: Thôn Sơn Hải, xã Phước Dinh, tỉnh Khánh Hòa | T27: =SUM(H27:S27) -> 0
A28: 8 | B28: Nhà máy điện mặt trời Hồ Bầu Ngứ | C28: Công ty cổ phần Đầu tư xây dựng và Phát triển Trường Thành | D28: Xã Phước Dinh, tỉnh Khánh Hòa | T28: =SUM(H28:S28) -> 0
A29: 9 | B29: Nhà máy điện mặt trời Hồ Núi Một | C29: Công ty cổ phần Đầu tư xây dựng và Phát triển Trường Thành | D29: Thôn Bầu Ngứ, xã Phước Dinh, tỉnh Khánh Hòa | T29: =SUM(H29:S29) -> 0
A30: 10 | B30: Nhà máy điện mặt trời KN Cam Lâm | C30: Công ty cổ phần Điện mặt trời KN Cam Lâm | D30: Thôn Tân An, xã Cam An, tỉnh Khánh Hòa | T30: =SUM(H30:S30) -> 0
A31: 11 | B31: Nhà máy điện mặt trời KN Vạn Ninh | C31: Công ty TNHH Đầu tư và Phát triển Điện mặt trời KN Vạn Ninh | D31: Thôn Xuân Tây, xã Vạn Hưng, tỉnh Khánh Hòa | T31: =SUM(H31:S31) -> 0
A32: 12 | B32: Nhà máy điện mặt trời Long Sơn | C32: Công ty cổ phần Năng lượng Long Sơn | D32: Thôn Đá Bàn, phường Bắc Ninh Hòa, tỉnh Khánh Hòa | T32: =SUM(H32:S32) -> 0
... A65: 45 | B65: Nhà máy điện mặt trời Sinenergy Ninh Thuận 1 | C65: Công ty TNHH Năng lượng Sinenergy Ninh Thuận | D65: Thôn Tân Đức, xã Phước Hữu, tỉnh Khánh Hòa | T65: =SUM(H65:S65) -> 0
A66: TỔNG | E66: =SUM(E21:E65) -> 0 | F66: =SUM(F21:F65) -> 0 | G66: =SUM(G21:G65) -> 0 | H66: =SUM(H21:H65) -> 0 | I66: =SUM(I21:I65) -> 0 | J66: =SUM(J21:J65) -> 0 | K66: =SUM(K21:K65) -> 0 | L66: =SUM(L21:L65) -> 0 | ... S66: =SUM(S21:S65) -> 0 | T66: =SUM(H66:S66) -> 0
A67: III | B67: NHÀ MÁY THỦY ĐIỆN (14 nhà máy) | T67: =SUM(H67:S67) -> 0
A68: 1 | B68: Nhà máy thủy điện Đa Nhim | C68: Công ty cổ phần Thủy điện Đa Nhim – Hàm Thuận – Đa Mi | D68: Xã Lâm Sơn, tỉnh Khánh Hòa | T68: =SUM(H68:S68) -> 0
A69: 2 | B69: Nhà máy thủy điện Sông Pha | C69: Công ty cổ phần Thủy điện Đa Nhim – Hàm Thuận – Đa Mi | D69: Xã Lâm Sơn, tỉnh Khánh Hòa | T69: =SUM(H69:S69) -> 0
A70: 3 | B70: Nhà máy thủy điện Đa Nhim mở rộng | C70: Công ty cổ phần Thủy điện Đa Nhim – Hàm Thuận – Đa Mi | D70: Xã Lâm Sơn, tỉnh Khánh Hòa | T70: =SUM(H70:S70) -> 0
A71: 4 | B71: Nhà máy thủy điện Hạ Sông Pha 1 | C71: Công ty cổ phần thủy điện Hạ Sông Pha | D71: Thôn Lâm Hà, xã Lâm Sơn, tỉnh Khánh Hòa | T71: =SUM(H71:S71) -> 0
A72: 5 | B72: Nhà máy thủy điện Hạ Sông Pha 2 | C72: Công ty cổ phần thủy điện Hạ Sông Pha | D72: Thôn Lâm Hà, xã Lâm Sơn, tỉnh Khánh Hòa | T72: =SUM(H72:S72) -> 0
A73: 6 | B73: Nhà máy thủy điện Mỹ Sơn | C73: Công ty cổ phần Thủy điện Mỹ Sơn | D73: Thôn Tân Mỹ, xã Mỹ Sơn, tỉnh Khánh Hòa | T73: =SUM(H73:S73) -> 0
...
