Workbook
Name _Hlk213525272_1: #REF!
Name _Hlk213525272_1: #REF!
Name df: #REF!
Name df: #REF!
Name ff: #REF!
Name GTB: #REF!
Name GXD: #REF!
Name H: #REF!

Sheet TongHopDuToan
A2: BẢNG CHI TIẾT TỔNG DỰ TOÁN
A3: ='3.Tổng hợp chi phí phần mềm'!A6:F6 -> Phần mềm Hệ thống thông tin báo cáo - Sở Du lịch KHA
A4: Đơn vị tính: VNĐ
A5: TT | B5: Nội dung | C5: Ký hiệu | D5: Công thức | E5: Giá trị trước thuế | F5: Thuế GTGT | G5: Giá trị sau thuế | H5: Ghi chú
A6: A | B6: CHI PHÍ TRIỂN KHAI PHẦN MỀM | C6: Gpm | E6: =SUM(E7:E8) -> 1.8772913e+08 | F6: 0 | G6: =E6+F6 -> 1.8772913e+08
A7: 1 | B7: Chi phí phần mềm | C7: Gpm1 | E7: ='3.Tổng hợp chi phí phần mềm'!E13 -> 1.8772913e+08 | F7: 0 | G7: =E7+F7 -> 1.8772913e+08 | H7: Chi tiết tại ChiPhiThue-PM
A8: 2 | B8: Chi phí thuê hạ tầng hàng năm | C8: Gpm2 | E8: 0 | F8: 0 | G8: 0 | H8: Chạy trên CSDL của Tỉnh.
A9: B | B9: CHI PHÍ QUẢN LÝ | C9: Gql | D9: 2,644%*Gpm | E9: =0.02644*E6 -> 4963558.1 | F9: =E9*0.1 -> 496355.81 | G9: =E9+F9 -> 5459914 | H9: 1688/QĐ-BTTTT
A10: C | B10: CHI PHÍ TƯ VẤN | C10: Gtv | E10: =SUM(E11:E12) -> 2622575.9 | F10: =SUM(F11:F12) -> 262257.59 | G10: =SUM(E10:F10) -> 2884833.5 | H10: 1688/QĐ-BTTTT
A11: 1 | B11: Chi phí lập Đề cương và dự toán chi tiết | C11: Gtv1 | D11: 0,992%*Gpm | E11: =0.00992*E6 -> 1862272.9 | F11: =E11*0.1 -> 186227.29 | G11: =E11+F11 -> 2048500.2 | H11: 1688/QĐ-BTTTT
A12: 2 | B12: Chi phí tư vấn lập Hồ sơ mời thầu và đánh giá Hồ sơ dự thầu | C12: Gtv2 | D12: 0,405%*Gpm | E12: =0.00405*E6 -> 760302.97 | F12: =E12*0.1 -> 76030.297 | G12: =E12+F12 -> 836333.26 | H12: 1688/QĐ-BTTTT
A13: D | B13: CHI PHÍ KHÁC | C13: Gk | E13: =SUM(E14:E17) -> 537468.49 | F13: =SUM(F14:F17) -> 53746.849 | G13: =SUM(E13:F13) -> 591215.34
A14: 1 | B14: Chi phí thẩm định hồ sơ mời thầu | C14: Gk1 | D14: 0,05%*Gpm | E14: =0.0005*E6 -> 93864.564 | F14: =E14*10% -> 9386.4564 | G14: =E14+F14 -> 103251.02 | H14: 63/2014/NĐ-CP
A15: 2 | B15: Chi phí thẩm định kết quả lựa chọn nhà thầu | C15: Gk2 | D15: 0,03%*Gpm | E15: =0.0003*E6 -> 56318.738 | F15: =E15*10% -> 5631.8738 | G15: =E15+F15 -> 61950.612 | H15: 63/2014/NĐ-CP
A16: 4 | B16: Chi phí giám sát | C16: Gk4 | D16: 2,063%*Gpm | E16: =0.002063*E6 -> 387285.19 | F16: =0.1*E16 -> 38728.519 | G16: =SUM(E16:F16) -> 426013.71 | H16: 1688/QĐ-BTTTT
A17: 6 | B17: Chi phí thẩm định giá | C17: Gk6 | H17: Đơn vị thuê ngoài báo giá thẩm định giá.
A18: E | B18: CHI PHÍ DỰ PHÒNG | C18: Gdp | E18: 0 | F18: 0 | G18: =SUM(E18:F18) -> 0
A19: TỔNG CỘNG | F19: =F6+F9+F10+F13+F18 -> 812360.26 | G19: =SUM(G6+G9+G10+G13+G18) -> 1.9666509e+08
A20: TỔNG DỰ TOÁN (làm tròn) | G20: =ROUND(G19,-3) -> 196665000
A21: Bằng chữ: ..................................

Sheet 3.Tổng hợp chi phí phần mềm
A1: VIỄN THÔNG KHÁNH HÒA
A2: TRUNG TÂM CÔNG NGHỆ THÔNG TIN
A5: TỔNG HỢP CHI PHÍ PHẦN MỀM
A6: Phần mềm Hệ thống thông tin báo cáo - Sở Du lịch KHA
F8: Đơn vị tính: đồng
A9: TT | B9: Khoản mục chi phí | C9: Ký hiệu | D9: Cách tính | E9: Giá trị | F9: Ghi chú
A10: 1 | B10: Giá trị phần mềm | C10: G | D10: 1,4 x E x P x H | E10: ='G.Giá trị phần mềm'!F20 -> 1.0733512e+08 | F10: Tham khảo sheet G.Giá trị phần mềm
A11: 2 | B11: Chi phí chung | C11: C | D11: G x 65% | E11: =65%*(E10) -> 69767829 | F11: Theo hướng dẫn 2589/BTTTT-ƯDCNTT
A12: 3 | B12: Thu nhập chịu thuế tính trước | C12: TL | D12: (G+C) x 6% | E12: =6%*(E10+E11) -> 10626177
A13: 4 | B13: Chi phí sản xuất phần mềm | C13: Gsx | D13: G + C + TL | E13: =SUM(E10:E12) -> 1.8772913e+08

Sheet G.Giá trị phần mềm
A1: ='3.Tổng hợp chi phí phần mềm'!A1 -> VIỄN THÔNG KHÁNH HÒA
A2: ='3.Tổng hợp chi phí phần mềm'!A2 -> TRUNG TÂM CÔNG NGHỆ THÔNG TIN
A5: BẢNG TÍNH TOÁN GIÁ TRỊ PHẦN MỀM
A6: ='3.Tổng hợp chi phí phần mềm'!A6:F6 -> Phần mềm Hệ thống thông tin báo cáo - Sở Du lịch KHA
A9: STT | B9: Hạng mục | C9: Ký hiệu | D9: ĐVT | E9: Diễn giải | F9: Giá trị | G9: Ghi chú
A10: I | B10: Tính điểm trường hợp sử dụng (Use-case)
A11: 1 | B11: - Điểm Actor (TAW) | C11: TAW | D11: Điểm | E11: TAW | F11: ='TAW.Điểm các tác nhân (actors)'!F12 -> 6 | G11: Tham khảo sheet TAW.Điểm các tác nhân (actors)
A12: 2 | B12: - Điểm Use case (TBF) | C12: TBF | D12: Điểm | E12: TBF | F12: ='TBF.Điểm USE-CASE'!F21 -> 260 | G12: Tham khảo sheet TBF.Điểm USE-CASE
A13: 3 | B13: - Tính điểm UUCP | C13: UUCP | D13: Điểm | E13: UUCP = TAW + TBF | F13: =F11+F12 -> 266
A14: 4 | B14: - Điểm hệ số phức tạp kỹ thuật công nghệ (TCF) | C14: TCF | D14: Điểm | E14: TCF = 0,6 + (0,01*TFW) | F14: ='TCF.Hệ số phức tạp KT-CN'!F23 -> 0.89 | G14: Tham khảo sheet TCF.Hệ số phức tạp KT-CN
A15: 5 | B15: - Điểm hệ số phức tạp môi trường (EF) | C15: EF | D15: Điểm | E15: EF = 1,4 + (-0,03 * EFW) | F15: =1.4-0.03*'EFW.Hệ số tác động môi trường'!F9 -> 0.125 | G15: Tham khảo sheet EFW.Hệ số tác động môi trường
A16: 6 | B16: - Tính điểm AUCP | C16: AUCP | D16: Điểm | E16: AUCP = UUCP * TCF * EF | F16: =F13*F14*F15 -> 29.5925
A17: II | B17: Nội suy thời gian lao động (P) | C17: P | E17: P = người/giờ/AUCP | F17: ='EFW.Hệ số tác động môi trường'!H21 -> 32 | G17: Tham khảo sheet EFW.Hệ số tác động môi trường
A18: III | B18: Giá trị nỗ lực thực tế (E) | C18: E | E18: E = AUCP*10/6 | F18: =F16*10/6 -> 49.320833
A19: IV | B19: Mức lương lao động bình quân (H) | C19: H | D19: Đồng | E19: H = người/giờ | F19: ='Bảng lương nhân công'!G11 -> 48577.307 | G19: Kỹ sư bậc 3. Tham khảo sheet Bảng lương nhân công.
A20: V | B20: Giá trị phần mềm nội bộ (G) | C20: G | D20: Đồng | E20: G=1,4*E*P*H | F20: =1.4*F18*F17*F19 -> 1.0733512e+08

Sheet USE-CASE
A1: ='3.Tổng hợp chi phí phần mềm'!A1 -> VIỄN THÔNG KHÁNH HÒA
A2: ='3.Tổng hợp chi phí phần mềm'!A2 -> TRUNG TÂM CÔNG NGHỆ THÔNG TIN
A5: BẢNG CHUYỂN ĐỔI YÊU CẦU CHỨC NĂNG SANG TRƯỜNG HỢP SỬ DỤNG (USE-CASE)
A6: ='3.Tổng hợp chi phí phần mềm'!A6:F6 -> Phần mềm Hệ thống thông tin báo cáo - Sở Du lịch KHA
A8: STT | B8: Tên Use Case | C8: Tác nhân chính | D8: Tác nhân phụ | E8: Mức độ BMT | F8: Mô tả trường hợp | G8: Phân loại Use Case
A9: I. Hệ thống
A10: 1 | B10: Quản lý người dùng | C10: Sở Du lịch | E10: B | F10: - Thêm / xóa / sửa người dùng. - Quản lý danh sách người dùng của Doanh nghiệp / Sở Du lịch. - Quản trị viên có thể reset mật khẩu người dùng. | G10: Đơn giản
A11: 2 | B11: Quản trị phân quyền | C11: Sở Du lịch | E11: B | F11: - Thực hiện phân quyền chức năng và phân quyền dữ liệu cho người dùng. | G11: Đơn giản
A12: 3 | B12: Cấu hình hệ thống | C12: Sở Du lịch | E12: B | F12: - Quản lý các cấu hình hệ thống. | G12: Đơn giản
A13: 4 | B13: Quản lý đăng nhập/đăng xuất | C13: Sở Du lịch / Doanh nghiệp | E13: B | F13: - Quản lý thông tin đăng nhập. - Người dùng tự thay đổi mật khẩu. | G13: Đơn giản
A14: 5 | B14: Cấu hình thời gian nộp báo cáo | C14: Sở Du lịch | E14: B | F14: - Cấu hình thông số thời gian hết hạn báo cáo: 24g00 ngày 12 hàng tháng. Các doanh nghiệp nộp báo cáo sau thời gian này chuyển trạng thái sang trễ hạn. - Từ ngày 12-18 hàng tháng, cho phép nộp báo cáo bổ sung cho các doanh nghiệp chưa nộp hoặc đã nộp và muốn điều chỉnh. - Sau 24g00 ngày 18 hàng tháng, chức năng import báo cáo của Doanh nghiệp sẽ bị khóa. - Sở Du lịch tự chủ động cấu hình thời gian nộp báo cáo cho Doanh nghiệp. | G14: Trung bình
A15: II. Nghiệp vụ gửi báo cáo
A16: 6 | B16: Gửi nộp báo cáo cho DN thuộc lĩnh vực lưu trú | C16: Doanh nghiệp | D16: Sở Du lịch | E16: B | F16: - Doanh nghiệp thực hiện import các mẫu báo cáo theo danh mục báo cáo đã có sẵn. | G16: Trung bình
A17: 7 | B17: Gửi nộp báo cáo cho DN thuộc lĩnh vực lữ hành | C17: Doanh nghiệp | D17: Sở Du lịch | E17: B | F17: - Doanh nghiệp thực hiện import các mẫu báo cáo theo danh mục báo cáo đã có sẵn. | G17: Trung bình
A18: 8 | B18: Gửi nộp báo cáo cho DN thuộc lĩnh vực vận chuyển khách du lịch. | C18: Doanh nghiệp | D18: Sở Du lịch | E18: B | F18: - Doanh nghiệp thực hiện import các mẫu báo cáo theo danh mục báo cáo đã có sẵn. | G18: Trung bình
A19: 9 | B19: Gửi nộp báo cáo cho DN thuộc lĩnh vực khu/điểm du lịch. | C19: Doanh nghiệp | D19: Sở Du lịch | E19: B | F19: - Doanh nghiệp thực hiện import các mẫu báo cáo theo danh mục báo cáo đã có sẵn. | G19: Trung bình
A20: 10 | B20: Gửi nộp báo cáo cho DN thuộc lĩnh vực phục vụ khách du lịch. | C20: Doanh nghiệp | D20: Sở Du lịch | E20: B | F20: - Doanh nghiệp thực hiện import các mẫu báo cáo theo danh mục báo cáo đã có sẵn. | G20: Trung bình
A21: 11 | B21: Gửi nộp báo cáo bổ sung cho DN. | C21: Doanh nghiệp | D21: Sở Du lịch | E21: B | F21: - Doanh nghiệp sau ngày 18 hàng tháng chưa nộp báo cáo, sẽ được nộp bổ sung tại menu chức năng này. Và chỉ những Doanh nghiệp này mới thấy menu này để thực hiện. | G21: Trung bình
A22: III. Nghiệp vụ quản lý
A23: 12 | B23: Kết xuất, tổng hợp báo cáo. | C23: Sở Du lịch | E23: B | F23: - Kết xuất các mẫu báo cáo theo các lĩnh vực: Lưu trú, lữ hành, vận chuyển, khu du lịch, phụ vụ du khách. | G23: Trung bình
A24: 13 | B24: Quản lý thông tin chung của Doanh nghiệp. | C24: Sở Du lịch | D24: Doanh nghiệp | E24: B | F24: - Thêm, xóa, sửa thông tin doanh nghiệp. - Cập nhật phân cấp các đơn vị cơ sở thuộc doanh nghiệp chủ đầu tư. | G24: Trung bình
A25: 14 | B25: Quản lý thông tin Doanh nghiệp thuộc lĩnh vực lưu trú. | C25: Sở Du lịch | D25: Doanh nghiệp | E25: B | F25: - Thêm, xóa, sửa thông tin doanh nghiệp. - Cập nhật phân cấp các đơn vị cơ sở thuộc doanh nghiệp chủ đầu tư. | G25: Trung bình
A26: 15 | B26: Quản lý thông tin Doanh nghiệp thuộc lĩnh vực lữ hành. | C26: Sở Du lịch | D26: Doanh nghiệp | E26: B | F26: - Thêm, xóa, sửa thông tin doanh nghiệp. - Cập nhật phân cấp các đơn vị cơ sở thuộc doanh nghiệp chủ đầu tư. | G26: Trung bình
A27: 16 | B27: Quản lý thông tin Doanh nghiệp thuộc lĩnh vực vận chuyển khách du lịch. | C27: Sở Du lịch | D27: Doanh nghiệp | E27: B | F27: - Thêm, xóa, sửa thông tin doanh nghiệp. - Cập nhật phân cấp các đơn vị cơ sở thuộc doanh nghiệp chủ đầu tư. | G27: Trung bình
A28: 17 | B28: Quản lý thông tin Doanh nghiệp thuộc lĩnh vực khu/điểm du lịch. | C28: Sở Du lịch | D28: Doanh nghiệp | E28: B | F28: - Thêm, xóa, sửa thông tin doanh nghiệp. - Cập nhật phân cấp các đơn vị cơ sở thuộc doanh nghiệp chủ đầu tư. | G28: Trung bình
A29: 18 | B29: Quản lý thông tin Doanh nghiệp thuộc lĩnh vực phục vụ khách du lịch. | C29: Sở Du lịch | D29: Doanh nghiệp | E29: B | F29: - Thêm, xóa, sửa thông tin doanh nghiệp. - Cập nhật phân cấp các đơn vị cơ sở thuộc doanh nghiệp chủ đầu tư. | G29: Trung bình
A30: 19 | B30: Thông báo bằng Email/SMS DS các Doanh nghiệp chưa nộp báo cáo. | C30: Sở Du lịch | D30: Doanh nghiệp | E30: B | F30: - Hệ thống gửi email tới DS tài khoản email của Sở Du lịch và Doanh nghiệp đã được cấu hình để thông báo DS các Doanh nghiệp chưa nộp báo cáo. - Sở Du lịch có thể thực hiện nhân công, hoặc để hệ thống tự động gửi thông báo. - Có thể sử dụng dịch vụ SMS Brandname. | G30: Trung bình
A31: 20 | B31: Tích hợp chức năng ký số điện tử. | C31: Sở Du lịch | D31: Doanh nghiệp | E31: B | F31: - Tích hợp chức năng ký số điện tử cho các Doanh nghiệp khi nộp gửi báo cáo. - Có thể sử dụng trên nền tảng online. | G31: Trung bình
A32: 21 | B32: Tích hợp chức năng chạy quảng cáo trên phần mềm. | C32: Sở Du lịch | E32: B | F32: - Tích hợp chức năng chạy quảng cáo, đưa các nội dung quảng cáo lên phần mềm. | G32: Trung bình
A33: 22 | B33: Kiểm tra sự biến động bất thường của số liệu báo cáo. | C33: Sở Du lịch | E33: B | F33: - Kiểm tra, rà soát sự biến động bất thường của số liệu báo cáo khi DN gửi về. - Sở Du lịch sẽ cung cấp các thông tin cận trên / cận dưới của số liệu với các trường thông tin cụ thể để thực hiện cấu hình rà soát sự biến động. | G33: Trung bình
A34: 23 | B34: Tích hợp, kết nối tới các hệ thống liên quan thông qua API được cung cấp. | C34: Sở Du lịch | E34: B | F34: - Tích hợp tới các hệ thống liên quan thông qua API được cung cấp. | G34: Trung bình
A35: IV. Danh mục
A36: 24 | B36: Quản lý danh mục kỳ báo cáo. | C36: Sở Du lịch | E36: B | F36: - Thêm, xóa, sửa danh mục kỳ báo cáo: tháng, quý, 06 tháng, năm… | G36: Đơn giản
A37: 25 | B37: Quản lý danh mục lĩnh vực kinh doanh của Doanh nghiệp. | C37: Sở Du lịch | E37: B | F37: - Thêm, xóa, sửa danh mục loại doanh nghiệp: lưu trú, lữ hành… | G37: Đơn giản
A38: V. Báo cáo thống kê
A39: 26 | B39: Thống kê danh sách doanh nghiệp trễ hạn báo cáo theo thời gian. | C39: Sở Du lịch | D39: Doanh nghiệp | E39: B | F39: - Thống kê DS doanh nghiệp trễ hạn báo cáo theo tháng/quý/năm… | G39: Trung bình
A40: 27 | B40: Thống kê danh sách doanh nghiệp chưa nộp báo cáo. | C40: Sở Du lịch | D40: Doanh nghiệp | E40: B | F40: - Thống kê DS doanh nghiệp trễ hạn báo cáo theo tháng/quý/năm… | G40: Trung bình
A41: 28 | B41: Thống kê số lượng báo cáo đã thực hiện trong tháng. | C41: Sở Du lịch | D41: Doanh nghiệp | E41: B | F41: - Thống kê số lượng báo cáo đã gửi / xuất trong tháng. | G41: Trung bình
A42: 29 | B42: Thống kê số lượng doanh nghiệp theo từng lĩnh vực. | C42: Sở Du lịch | D42: Doanh nghiệp | E42: B | F42: - Thống kê số lượng doanh nghiệp theo lĩnh vực. | G42: Trung bình
B45: Tổng Use case : | C45: B
...

Sheet TBF.Điểm USE-CASE
A1: ='3.Tổng hợp chi phí phần mềm'!A1 -> VIỄN THÔNG KHÁNH HÒA
A2: ='3.Tổng hợp chi phí phần mềm'!A2 -> TRUNG TÂM CÔNG NGHỆ THÔNG TIN
A5: BẢNG TÍNH TOÁN ĐIỂM CÁC TRƯỜNG HỢP SỬ DỤNG (USE-CASE)
A6: ='3.Tổng hợp chi phí phần mềm'!A6:F6 -> Phần mềm Hệ thống thông tin báo cáo - Sở Du lịch KHA
A8: TT | B8: Loại | C8: Số trường hợp sử dụng | D8: Trọng số | E8: Hệ số BMT | F8: Điểm của từng loại trường hợp sử dụng | G8: Mô tả
A9: 1 | B9: B | G9: Các yêu cầu phải thỏa mãn thì phần mềm mới được chấp nhận. Use-case đơn giản <= 3 transactions hoặc đường chỉ thị.
B10: Đơn giản | C10: ='USE-CASE'!D46 -> 6 | D10: 5 | E10: 1 | F10: =C10*D10*E10 -> 30
B11: Trung bình | C11: ='USE-CASE'!D47 -> 23 | D11: 10 | E11: 1 | F11: =C11*D11*E11 -> 230
B12: Phức tạp | C12: ='USE-CASE'!D48 -> 0 | D12: 15 | E12: 1 | F12: =C12*D12*E12 -> 0
A13: 2 | B13: M | G13: Các chức năng không phải là cốt lõi hay các chức năng phụ trợ hoặc theo yêu cầu của bên đặt hàng. Use-case trung bình từ 4 đến 7 transactions.
B14: Đơn giản | C14: ='USE-CASE'!D50 -> 0 | D14: 5 | E14: 1.2 | F14: =C14*D14*E14 -> 0
B15: Trung bình | C15: ='USE-CASE'!D51 -> 0 | D15: 10 | E15: 1.2 | F15: =C15*D15*E15 -> 0
B16: Phức tạp | C16: ='USE-CASE'!D52 -> 0 | D16: 15 | E16: 1.2 | F16: =C16*D16*E16 -> 0
A17: 3 | B17: T | G17: Các yêu cầu được tư vấn thêm hoặc đưa ra để bên đặt hàng lựa chọn thêm nếu muốn. Use-case phức tạp > 7 transactions
B18: Đơn giản | C18: ='USE-CASE'!D54 -> 0 | D18: 5 | E18: 1.5 | F18: =C18*D18*E18 -> 0
B19: Trung bình | C19: ='USE-CASE'!D55 -> 0 | D19: 10 | E19: 1.5 | F19: =C19*D19*E19 -> 0
B20: Phức tạp | C20: ='USE-CASE'!D56 -> 0 | D20: 15 | E20: 1.5 | F20: =C20*D20*E20 -> 0
B21: Cộng (1+2+3) | C21: =SUM(C10:C20) -> 29 | F21: =SUM(F10:F20) -> 260 | G21: TBF

Sheet TAW.Điểm các tác nhân (actors)
A1: ='3.Tổng hợp chi phí phần mềm'!A1 -> VIỄN THÔNG KHÁNH HÒA
A2: ='3.Tổng hợp chi phí phần mềm'!A2 -> TRUNG TÂM CÔNG NGHỆ THÔNG TIN
A5: BẢNG TÍNH TOÁN ĐIỂM CÁC TÁC NHÂN (ACTORS) TƯƠNG TÁC, TRAO ĐỔI THÔNG TIN
A6: ='3.Tổng hợp chi phí phần mềm'!A6:F6 -> Phần mềm Hệ thống thông tin báo cáo - Sở Du lịch KHA
A8: TT | B8: Loại Actor | C8: Mô tả | D8: Số tác nhân | E8: Trọng số | F8: Điểm của từng loại tác nhân | G8: Ghi chú
A9: 1 | B9: Đơn giản (simple actor) | C9: Thuộc loại giao diện của chương trình | D9: 0 | E9: 1 | F9: =D9*E9 -> 0
A10: 2 | B10: Trung bình (average actor) | C10: Giao diện tương tác hoặc phục vụ một giao thức hoạt động | D10: 0 | E10: 2 | F10: =D10*E10 -> 0
A11: 3 | B11: Phức tạp (complex actor) | C11: Giao diện đồ họa | D11: 2 | E11: 3 | F11: =D11*E11 -> 6
B12: Cộng (1+2+3) | C12: TAW | F12: =SUM(F9:F11) -> 6
A14: Stt | B14: Actors | C14: Loại Actor
A15: 1 | B15: Sở Du lịch | C15: Phức tạp
A16: 2 | B16: Doanh nghiệp | C16: Phức tạp

Sheet TCF.Hệ số phức tạp KT-CN
A1: ='3.Tổng hợp chi phí phần mềm'!A1 -> VIỄN THÔNG KHÁNH HÒA
A2: ='3.Tổng hợp chi phí phần mềm'!A2 -> TRUNG TÂM CÔNG NGHỆ THÔNG TIN
A5: BẢNG TÍNH TOÁN HỆ SỐ PHỨC TẠP KỸ THUẬT-CÔNG NGHỆ
A6: ='3.Tổng hợp chi phí phần mềm'!A6:F6 -> Phần mềm Hệ thống thông tin báo cáo - Sở Du lịch KHA
A8: STT | B8: Các hệ số | C8: Mức giá trị xếp hạng | D8: Giá trị xếp hạng | E8: Trọng số | F8: Kết quả | G8: Ghi chú
A9: I | B9: Hệ số KT-CN (TFW) | F9: =SUM(F10:F22) -> 29
A10: 1 | B10: Hệ thống phân tán (Distributed System) | C10: Giá trị xếp hạng được xác định trong khoảng từ 0 đến 5 với ý nghĩa: 0 = Không quan trọng; 5 = Có vai trò tác động căn bản; | D10: 1 | E10: 3 | F10: =D10*E10 -> 3
A11: 2 | B11: Tính chất đáp ứng tức thời hoặc yêu cầu đảm bảo thông lượng (response throughput performance objectives) | D11: 1 | E11: 1 | F11: =D11*E11 -> 1
A12: 3 | B12: Hiệu quả sử dụng trực tuyến (end user efficiency online) | D12: 1 | E12: 1 | F12: =D12*E12 -> 1
A13: 4 | B13: Độ phức tạp của xử lý bên trong (complex internal processing) | D13: 3 | E13: 1 | F13: =D13*E13 -> 3
A14: 5 | B14: Mã nguồn phải tái sử dụng được (Code must be reuseable) | D14: 2 | E14: 1 | F14: =D14*E14 -> 2
A15: 6 | B15: Dễ cài đặt (Easy to install) | D15: 4 | E15: 0.5 | F15: =D15*E15 -> 2
A16: 7 | B16: Dễ sử dụng (Easy to use) | D16: 4 | E16: 0.5 | F16: =D16*E16 -> 2
A17: 8 | B17: Khả năng chuyển đổi (Portable) | D17: 2 | E17: 2 | F17: =D17*E17 -> 4
A18: 9 | B18: Khả năng dễ thay đổi (Easy to change) | D18: 1 | E18: 1 | F18: =D18*E18 -> 1
A19: 10 | B19: Sử dụng đồng thời (Concurrent) | D19: 2 | E19: 1 | F19: =D19*E19 -> 2
A20: 11 | B20: Có các tính năng bảo mật đặc biệt | D20: 3 | E20: 2 | F20: =D20*E20 -> 6
A21: 12 | B21: Cung cấp truy nhập trực tiếp tới các phần mềm third party | D21: 0 | E21: 1 | F21: =D21*E21 -> 0
A22: 13 | B22: Yêu cầu phương tiện đào tạo đặc biệt cho người sử dụng | D22: 2 | E22: 1 | F22: =D22*E22 -> 2
A23: II | B23: Hệ số độ phức tạp về KT-CN (TCF) | C23: TCF = 0,6 + (0,01 x TFW) | F23: =0.6+0.01*F9 -> 0.89

Sheet EFW.Hệ số tác động môi trường
A1: ='3.Tổng hợp chi phí phần mềm'!A1 -> VIỄN THÔNG KHÁNH HÒA
A2: ='3.Tổng hợp chi phí phần mềm'!A2 -> TRUNG TÂM CÔNG NGHỆ THÔNG TIN
A5: BẢNG TÍNH TOÁN HỆ SỐ TÁC ĐỘNG MÔI TRƯỜNG VÀ NHÓM LÀM VIỆC, HỆ SỐ PHỨC TẠP VỀ MÔI TRƯỜNG
A6: ='3.Tổng hợp chi phí phần mềm'!A6:F6 -> Phần mềm Hệ thống thông tin báo cáo - Sở Du lịch KHA
A8: STT | B8: Các hệ số tác động môi trường | C8: Thang điểm đánh giá giá trị xếp hạng | D8: Trọng số | E8: Giá trị xếp hạng | F8: Kết quả (KQ) | G8: Thang điểm tính Giá trị nội suy từ Kết quả | H8: Đánh giá độ ổn định kinh nghiệm
A9: I | B9: Hệ số tác động môi trường và nhóm làm việc (EFW) | F9: =SUM(F11:F18) -> 42.5
B10: Đánh giá cho từng thành viên | G10: KQ ≤0: GTNS=0 KQ>0: GTNS= 0,05 KQ>1: GTNS= 0,1 KQ>2: GTNS= 0,6 KQ>3: GTNS= 1
A11: 2 | B11: Có kinh nghiệm về ứng dụng tương tự (application experiences) | C11: . Điểm 0: Không có kinh nghiệm . Điểm 1: Trình độ yếu; . Điểm 3: Trung bình; . Điểm 5: Giỏi; (Chấp nhận điểm đánh giá lẻ 01 chữ số thập phân sau dấu phẩy) | D11: 1.5 | E11: 5 | F11: =D11*E11 -> 7.5 | H11: =IF(F11>3,1,IF(F11>2,0.6,IF(F11>1,0.1,IF(F11>0,0.05,0)))) -> 1
A12: 3 | B12: Có kinh nghiệm về hướng đối tượng (Object Oriented) | D12: 0.5 | E12: 5 | F12: =D12*E12 -> 2.5 | H12: =IF(F12>3,1,IF(F12>2,0.6,IF(F12>1,0.1,IF(F12>0,0.05,0)))) -> 0.6
A13: 4 | B13: Có khả năng lãnh đạo Nhóm | D13: 1 | E13: 5 | F13: =D13*E13 -> 5 | H13: =IF(F13>3,1,IF(F13>2,0.6,IF(F13>1,0.1,IF(F13>0,0.05,0)))) -> 1
A14: 5 | B14: Tính chất năng động | C14: . 0 = Không năng động . 3 = Trung bình . 5 = Cao | D14: 0.5 | E14: 5 | F14: =D14*E14 -> 2.5 | H14: =IF(F14>3,1,IF(F14>2,0.6,IF(F14>1,0.1,IF(F14>0,0.05,0)))) -> 0.6
B15: Đánh giá chung cho Dự án
A16: 1 | B16: Độ ổn định của các yêu cầu | C16: 0 = Rất bất định 5 = Không hay thay đổi | D16: 5 | E16: 5 | F16: =D16*E16 -> 25 | H16: =IF(F16>3,1,IF(F16>2,0.6,IF(F16>1,0.1,IF(F16>0,0.05,0)))) -> 1
A17: 2 | B17: Có sử dụng các nhân viên làm Part-time (một phần thời gian) | C17: 0 = Không có nhân viên làm Part-time 3 = Có nhân viên làm Part-time 5 = Tất cả đều làm Part-time | D17: -1 | E17: 0 | F17: =D17*E17 -> 0 | H17: =IF(F17>3,1,IF(F17>2,0.6,IF(F17>1,0.1,IF(F17>0,0.05,0)))) -> 0
A18: 3 | B18: Dùng ngôn ngữ lập trình loại khó | C18: 0 = Ngôn ngữ lập trình dễ 3 = Trung bình 5 = Khó | D18: -1 | E18: 0 | F18: =D18*E18 -> 0 | H18: =IF(F18>3,1,IF(F18>2,0.6,IF(F18>1,0.1,IF(F18>0,0.05,0)))) -> 0
A19: II | B19: Hệ số phức tạp về môi trường (EF = 1,4 + (-0,03 x EFW)) | C19: EF = 1,4 + (-0,03 x EFW) | H19: =1.4-0.03*F9 -> 0.125
A20: III | B20: Độ ổn định kinh nghiệm (ES) | H20: 2
A21: IV | B21: Nội suy thời gian lao động (P) | G21: ES< 1 P=48 ES≥ 1 P=32 ES≥ 3 P=20 | H21: =IF(H20>=3,20,IF(H20>=1,32,48)) -> 32

Sheet Bảng lương nhân công
B1: 7. BẢNG LƯƠNG
K2: ĐVT: đồng
A3: STT | B3: Hạng mục | C3: Cách tính | E3: KS bậc 1/7 | F3: KS 2/7 | G3: KS bậc 3/7 | H3: KS bậc 4/7 | I3: KS bậc 5/7 | J3: KS bậc 6/7 | K3: KS bậc 7/7 | L3: Ghi chú
A4: 1 | B4: Hệ số lương (HSL) | E4: =E22 -> 1.15 | F4: =F22 -> 1.38 | G4: =G22 -> 1.6675 | H4: =H22 -> 2.02125 | I4: =I22 -> 2.415 | J4: =J22 -> 2.9325 | K4: =K22 -> 3.45 | L4: Thông tư số 17/2015/TT-BLĐTBXH; NĐ 49/2013/NĐ-CP;
A5: 2 | B5: Lương tối thiểu vùng (LTTV) | E5: 4420000 | F5: 4420000 | G5: 4420000 | H5: 4420000 | I5: 4420000 | J5: 4420000 | K5: 4420000 | L5: Nghị định 90/2019/NĐ-CP ngày 15/11/2019
A6: 3 | B6: Mức lương (LCBDN) | D6: HSL*LTTV | E6: =E4*E5 -> 5083000 | F6: =F5*F4 -> 6099600 | G6: =G5*G4 -> 7370350 | H6: =H5*H4 -> 8933925 | I6: =I5*I4 -> 10674300 | J6: =J5*J4 -> 12961650 | K6: =K5*K4 -> 15249000
A7: 4 | B7: Lương phụ | C7: 0.12 | D7: * LCBDN | E7: =E6*12% -> 609960 | F7: =F6*12% -> 731952 | G7: =G6*12% -> 884442 | H7: =H6*12% -> 1072071 | I7: =I6*12% -> 1280916 | J7: =J6*12% -> 1555398 | K7: =K6*12% -> 1829880 | L7: TT 06/2011/TT - BTTTT
A8: 5 | B8: Khoán trực tiếp | C8: 0.04 | D8: * LCBDN | E8: =E6*4% -> 203320 | F8: =F6*4% -> 243984 | G8: =G6*4% -> 294814 | H8: =H6*4% -> 357357 | I8: =I6*4% -> 426972 | J8: =J6*4% -> 518466 | K8: =K6*4% -> 609960
A9: 6 | B9: Tổng lương/tháng | E9: =SUM(E6:E8) -> 5896280 | F9: =SUM(F6:F8) -> 7075536 | G9: =SUM(G6:G8) -> 8549606 | H9: =SUM(H6:H8) -> 10363353 | I9: =SUM(I6:I8) -> 12382188 | J9: =SUM(J6:J8) -> 15035514 | K9: =SUM(K6:K8) -> 17688840
A10: 7 | B10: Đơn giá nhân công/ngày | E10: =E9/22 -> 268012.73 | F10: =F9/22 -> 321615.27 | G10: =G9/22 -> 388618.45 | H10: =H9/22 -> 471061.5 | I10: =I9/22 -> 562826.73 | J10: =J9/22 -> 683432.45 | K10: =K9/22 -> 804038.18
A11: 8 | B11: Đơn giá nhân công/giờ | E11: =E10/8 -> 33501.591 | F11: =F10/8 -> 40201.909 | G11: =G10/8 -> 48577.307 | H11: =H10/8 -> 58882.688 | I11: =I10/8 -> 70353.341 | J11: =J10/8 -> 85429.057 | K11: =K10/8 -> 100504.77
A13: CÁCH TÍNH HỆ SỐ LƯƠNG
A15: STT | B15: Nhóm yếu tố | E15: Bậc 1 | F15: Bậc 2 | G15: Bậc 3 | H15: Bậc 4 | I15: Bậc 5 | J15: Bậc 6 | K15: Bậc 7
A16: 1 | B16: Thời gian hoặc trình độ đào tạo | E16: 12 | F16: 13 | G16: 14 | H16: 15 | I16: 16 | J16: 17 | K16: 18
A17: 2 | B17: Trách nhiệm | E17: 2 | F17: 3 | G17: 4 | H17: 5 | I17: 7 | J17: 8 | K17: 10
A18: 3 | B18: Kỹ năng, tích lũy kinh nghiệm | E18: 1 | F18: 2 | G18: 3 | H18: 4 | I18: 6 | J18: 8 | K18: 10
A19: 4 | B19: Mức độ ảnh hưởng của công việc, sản phẩm | E19: 0 | F19: 0 | G19: 1 | H19: 2 | I19: 3 | J19: 5 | K19: 7
A20: 5 | B20: Tổng điểm các yếu tố | E20: =SUM(E16:E19) -> 15 | F20: =SUM(F16:F19) -> 18 | G20: =SUM(G16:G19) -> 22 | H20: =SUM(H16:H19) -> 26 | I20: =SUM(I16:I19) -> 32 | J20: =SUM(J16:J19) -> 38 | K20: =SUM(K16:K19) -> 45
A21: 6 | B21: Hệ số cấp bậc công việc | E21: =E20/15 -> 1 | F21: =F20/15 -> 1.2 | G21: =MROUND(G20/15,0.05) -> 1.45 | H21: =MROUND(H20/15,0.05) -> 1.75 | I21: =ROUND(I20/15,1) -> 2.1 | J21: =MROUND(J20/15,0.05) -> 2.55 | K21: =K20/15 -> 3
A22: 7 | B22: Hệ số lương | E22: =E21+E21*15% -> 1.15 | F22: =F21+F21*15% -> 1.38 | G22: =G21+G21*15% -> 1.6675 | H22: =H21*15.5%+H21 -> 2.02125 | I22: =I21+I21*15% -> 2.415 | J22: =J21+J21*15% -> 2.9325 | K22: =K21+K21*15% -> 3.45
A24: TIÊU CHUẨN CHỨC DANH KỸ SƯ PHẦN MỀM, LẬP TRÌNH VIÊN
A26: STT | B26: Nhóm yếu tố | E26: Tiêu chí đánh giá | H26: Thang điểm kỹ thuật thấp nhất | J26: Thang điểm kỹ thuật cao nhất
A27: 1 | B27: Thời gian hoặc trình độ đào tạo | E27: Tốt nghiệp Cao đẳng, Đại học, được đào tạo kỹ thuật nghiệp vụ từ 6 tháng đến dưới 1 năm | H27: 12 | J27: 18
A28: 2 | B28: Trách nhiệm | E28: Yêu cầu trách nhiệm công việc cao | H28: 2 | J28: 10
A29: 3 | B29: Kỹ năng, tích lũy kinh nghiệm | E29: Công việc yêu cầu có kỹ năng, tích lũy kinh nghiệm từ 1-2 năm | H29: 1 | J29: 10
A30: 4 | B30: Mức độ ảnh hưởng của công việc, sản phẩm | E30: Công việc, sản phẩm ảnh hưởng quyết định đến công việc, sản phẩm khác | H30: 0 | J30: 7
B31: TỔNG ĐIỂM CÁC YẾU TỐ | H31: =SUM(H27:I30) -> 15 | J31: =SUM(J27:K30) -> 45

Sheet CHI PHÍ NHÂN CÔNG
A2: BẢNG TÍNH XÁC ĐỊNH MỨC THU NHẬP BÌNH QUÂN
A4: TT | B4: Hạng mục | C4: Cách tính | F4: KS bậc 1/8 | G4: KS bậc 2/8 | H4: KS bậc 3/8 | I4: KS bậc 4/8 | J4: KS bậc 5/8 | K4: KS bậc 6/8 | L4: KS bậc 7/8 | M4: KS bậc 8/8 | N4: Ghi chú
A5: 1 | B5: Hệ số | F5: 2.34 | G5: 2.65 | H5: 2.96 | I5: 3.27 | J5: 3.58 | K5: 3.89 | L5: 4.2 | M5: 4.51 | N5: 205/2004/NĐ-CP
A6: 2 | B6: Lương tối thiểu (LTT) | C6: 1 | D6: x | E6: 2000000 | F6: 2000000 | G6: 2000000 | H6: 2000000 | I6: 2000000 | J6: 2000000 | K6: 2000000 | L6: 2000000 | M6: 2000000
A7: 3 | B7: Lương cơ bản (LCB) | C7: Hệ số | D7: x | E7: LTT | F7: 4680000 | G7: 5300000 | H7: 5920000 | I7: 6540000 | J7: 7160000 | K7: 7780000 | L7: 8400000 | M7: 9020000
B8: Lương phụ (tiền ngày lễ, ngày phép) | C8: 0.12 | D8: x | E8: LCB | F8: 561600 | G8: 636000 | H8: 710400 | I8: 784800 | J8: 859200 | K8: 933600 | L8: 1008000 | M8: 1082400
B9: Chi phí khoán gọn cho người lao động (CPKG) | C9: 0.04 | D9: x | E9: LCB | F9: 187200 | G9: 212000 | H9: 236800 | I9: 261600 | J9: 286400 | K9: 311200 | L9: 336000 | M9: 360800
B10: Phụ cấp không ổn định sản xuất (PCSX) | C10: 0.1 | D10: x | E10: LCB | F10: 468000 | G10: 530000 | H10: 592000 | I10: 654000 | J10: 716000 | K10: 778000 | L10: 840000 | M10: 902000
A11: 4 | B11: Bảo hiểm xã hội | C11: 0.16 | D11: x | E11: LCB | F11: 748800 | G11: 848000 | H11: 947200 | I11: 1046400 | J11: 1145600 | K11: 1244800 | L11: 1344000 | M11: 1443200
A12: 5 | B12: Bảo hiểm y tế | C12: 0.03 | D12: x | E12: LCB | F12: 140400 | G12: 159000 | H12: 177600 | I12: 196200 | J12: 214800 | K12: 233400 | L12: 252000 | M12: 270600
A13: 6 | B13: Bảo hiểm thất nghiệp | C13: 0.01 | D13: x | E13: LCB | F13: 46800 | G13: 53000 | H13: 59200 | I13: 65400 | J13: 71600 | K13: 77800 | L13: 84000 | M13: 90200
A14: 7 | B14: Phụ cấp lưu động (PCLD) | C14: 0.15 | D14: x | E14: LTT | F14: 300000 | G14: 300000 | H14: 300000 | I14: 300000 | J14: 300000 | K14: 300000 | L14: 300000 | M14: 300000
A15: 8 | B15: Công đoàn phí | C15: 0.02 | D15: x | E15: LCB | F15: 93600 | G15: 106000 | H15: 118400 | I15: 130800 | J15: 143200 | K15: 155600 | L15: 168000 | M15: 180400
A16: 9 | B16: Ăn ca | C16: 1 | D16: x | E16: 620000 | F16: 620000 | G16: 620000 | H16: 620000 | I16: 620000 | J16: 620000 | K16: 620000 | L16: 620000 | M16: 620000
A17: 10 | B17: Tổng thu nhập/tháng | F17: 7846400 | G17: 8764000 | H17: 9681600 | I17: 10599200 | J17: 11516800 | K17: 12434400 | L17: 13352000 | M17: 14269600
B18: Đơn giá nhân công/ngày | F18: 356655 | G18: 398364 | H18: 440073 | I18: 481782 | J18: 523491 | K18: 565200 | L18: 606909 | M18: 648618
B19: Đơn giá giờ công | F19: 44582 | G19: 49796 | H19: 55009 | I19: 60223 | J19: 65436 | K19: 70650 | L19: 75864 | M19: 81077
B21: Đề xuất lựa chọn mức thu nhập bình quân theo mức 3 tại Bảng tính

Sheet CHI PHI NHAN CONG THEO VNPT
A1: TẬP ĐOÀN BƯU CHÍNH VIỄN THÔNG VIỆT NAM
A2: CÔNG TY ĐIỆN TOÁN VÀ TRUYỀN SỐ LIỆU
A4: BẢNG DIỄN GIẢI CÁCH TÍNH TIỀN LƯƠNG KỸ SƯ CNTT 2012
A5: Vùng I (Căn cứ theo Nghị định số 70/2011/NĐ-CP ngày 22/8/2011)
A7: STT | B7: Diễn giải cách tính | C7: Cách tính lương theo Định mức chi phí của TĐ | E7: Ghi chú
C8: Tiền lương | D8: Diễn giải cách tính
B9: Mức lương 2012 (đ/tháng) | C9: =SUM(C16:C23) -> 8122314.7
B10: Đơn giá ngày công (đ/ngày) | C10: =C9/22 -> 369196.12 | D10: Mức lương 2012 / 22
B11: Đơn giá giờ công (đ/giờ) | C11: =C10/8 -> 46149.515 | D11: Đơn giá ngày công/8
A12: 1 | B12: Hệ số lương | C12: 2.96
A13: 2 | B13: Lương tối thiểu chung từ tháng 1-4/2012 | C13: 830000
A14: 3 | B14: Lương tối thiểu chung từ tháng 5-12/2012 | C14: 1050000
A15: 4 | B15: Lương tối thiểu vùng | C15: 2000000
A16: 5 | B16: Lương cơ bản | C16: =C15*C12 -> 5920000 | D16: 2,96* Lương tối thiểu vùng
A17: 6 | B17: Lương phụ | C17: =C16*12% -> 710400 | D17: 2,96*(Lương tối thiểu vùng)*12% | E17: VB 2589/BTTTT
A18: 7 | B18: Bảo hiểm xã hội | C18: =C12*(C13*4+C14*8)/12*17% -> 491458.67 | D18: 2,96*(830.000*4+1.050.000*8)/12*17% | E18: Điều 2 Thông tư 10/2012/TT-BLĐTBXH ngày 26/4/2012 của BLĐTBXH
A19: 8 | B19: Bảo hiểm y tế | C19: =C12*(C13*4+C14*8)/12*3% -> 86728 | D19: 2,96*(830.000*4+1.050.000*8)/12*3%
A20: 9 | B20: Bảo hiểm thất nghiệp | C20: =C12*(C13*4+C14*8)/12*1% -> 28909.333 | D20: 2,96*(830.000*4+1.050.000*8)/12*1%
A21: 10 | B21: Công đoàn phí | C21: =C12*(C13*4+C14*8)/12*2% -> 57818.667 | D21: 2,96*(830.000*4+1.050.000*8)/12*2% | E21: Đ 26 Luật Công đoàn 2013
A22: 11 | B22: Ăn ca | C22: =(620000*4+680000*8)/12 -> 660000 | D22: (620.000*4+680.000*8)/12
A23: 12 | B23: Bảo hộ lao động | C23: =ROUND(2000000/12,-3) -> 167000 | D23: 2.000.000 đồng/người/năm
A24: Lưu ý: kỹ sư CNTT của VNPT là kỹ sư bậc 3/8
A25: Tên tỉnh/TP | B25: Phạm vi áp dụng
A26: Bà Rịa - Vũng Tàu | B26: Thành phố Vũng Tàu
A27: Bình Dương | B27: Các thị xã Thủ Dầu Một, Thuận An, Dĩ An và các huyện Bến Cát, Tân Uyên
A28: Đồng Nai | B28: Thành phố Biên Hòa và các huyện Nhơn Trạch, Long Thành, Vĩnh Cửu,Trảng Bom
A29: Hà Nội: | B29: Các quận và các huyện Gia Lâm, Đông Anh, Sóc Sơn, Thanh Trì, Từ Liêm,Thường Tín, Hòai Đức, Thạch Thất, Quốc Oai, Thanh Oai, Mê Linh, Chương Mỹ và thị xã Sơn Tây thuộc thành phố Hà Nội
A30: Hải Phòng | B30: Các quận và các huyện Thủy Nguyên, An Dương, An Lão, Vĩnh Bảo
A31: TP Hồ Chí Minh | B31: Các quận và các huyện Củ Chi, Hóc Môn, Bình Chánh, Nhà Bè
